<?xml version="1.0" ?>
<!-- =================================================================================== -->
<!-- |    This document was autogenerated by xacro from huron.xacro                    | -->
<!-- |    EDITING THIS FILE BY HAND IS NOT RECOMMENDED                                 | -->
<!-- =================================================================================== -->
<robot name="huron" xmlns:xacro="http://ros.org/wiki/xacro">

  <!-- Right leg -->
  <link name="body"/>
  <joint name="base_fixed" type="fixed">
    <origin rpy="0 0 0" xyz="0 0 0"/>
    <parent link="body"/>
    <child link="base_footprint"/>
  </joint>

  <!-- base_link -->
  <link name="base_footprint">
    <inertial>
      <origin rpy="0 0 0" xyz="4.7319E-09 5.4338E-07 0.026975"/>
      <mass value="3.4072"/>
      <inertia ixx="0.00319" ixy="7.149E-11" ixz="6.0313E-11" iyy="0.010531" iyz="6.926E-09" izz="0.012315"/>
    </inertial>
    <visual>
      <origin rpy="0 0 0" xyz="0 0 0"/>
      <geometry>
        <mesh filename="meshes/base_link.STL"/>
      </geometry>
    </visual>
  </link>

  <!-- Battery -->
  <link name="battery_link">
    <inertial>
      <origin rpy="0 0 0" xyz="0 0 0"/>
      <mass value="3.90089"/>
      <inertia ixx="0.01890143742" ixy="0" ixz="0" iyy="0.0128628597" iyz="0" izz="0.008785454428"/>
    </inertial>
    <visual>
      <origin rpy="0 0 0" xyz="0 0 0"/>
      <geometry>
        <box size="0.065 0.188 0.151"/>
      </geometry>
    </visual>
  </link>
  <joint name="battery_fixed" type="fixed">
    <origin rpy="0 0 0" xyz="0 0 0.0895"/>
    <parent link="base_footprint"/>
    <child link="battery_link"/>
  </joint>
  
  <!-- imu joint -->
  <joint name="imu_fixed" type="fixed">
    <origin rpy="0 0 0" xyz="0 0 0"/>
    <parent link="base_footprint"/>
    <child link="imu_link"/>
  </joint>
  <!-- right hip yaw joint -->
  <link name="imu_link"/>
  <joint name="r_hip_yaw_joint" type="revolute">
    <origin rpy="0 0 3.141592654" xyz="0.0774999999999944 0 -0.1451242"/>
    <parent link="base_footprint"/>
    <child link="r_hip_yaw_link"/>
    <axis xyz="0 0 1"/>
    <limit effort="1000" lower="-3.1416" upper="3.1416" velocity="3"/>
    <!--<dynamics damping="0.5" friction="5"/>-->
  </joint>
  <transmission name="r_hip_yaw_joint_tran">
    <type>transmission_interface/SimpleTransmission</type>
    <joint name="r_hip_yaw_joint">
    </joint>
    <actuator name="r_hip_yaw_joint_motor">
    </actuator>
  </transmission>
  <!-- right hip yaw link -->
  <link name="r_hip_yaw_link">
    <visual>
      <origin rpy="0 0 0" xyz="0 0 0"/>
      <geometry>
        <mesh filename="meshes/r_hip_yaw_link.STL"/>
      </geometry>
    </visual>
    <inertial>
      <origin rpy="0 0 0" xyz="0.0006244 0.00052023 0.063505"/>
      <mass value="1.6968"/>
      <inertia ixx="0.0022729" ixy="-5.6517E-10" ixz="6.6464E-06" iyy="0.0026746" iyz="5.6889E-09" izz="0.0012354"/>
    </inertial>
  </link>
  <!-- right hip roll joint-->
  <joint name="r_hip_roll_joint" type="revolute">
    <origin rpy="1.570796327 0 0" xyz="0 0 0"/>
    <parent link="r_hip_yaw_link"/>
    <child link="r_hip_roll_link"/>
    <axis xyz="0 0 1"/>
    <limit effort="1000" lower="-0.5236" upper="0.01" velocity="3"/>
    <!--<dynamics damping="0.5" friction="5"/>-->
  </joint>
  <transmission name="r_hip_roll_joint_tran">
    <type>transmission_interface/SimpleTransmission</type>
    <joint name="r_hip_roll_joint">
    </joint>
    <actuator name="r_hip_roll_joint_motor">
    </actuator>
  </transmission>
  <!-- right hip roll link -->
  <link name="r_hip_roll_link">
    <visual>
      <origin rpy="0 0 0" xyz="0 0 0"/>
      <geometry>
        <mesh filename="meshes/r_hip_roll_link.STL"/>
      </geometry>
    </visual>
    <inertial>
      <origin rpy="0 0 0" xyz="-0.07196 0.0061152 -0.00052563"/>
      <mass value="1.1884"/>
      <inertia ixx="0.00098222" ixy="9.8947E-08" ixz="9.2484E-09" iyy="0.00097045" iyz="9.7414E-08" izz="0.00092365"/>
    </inertial>
  </link>
  <!-- right hip pitch joint -->
  <joint name="r_hip_pitch_joint" type="revolute">
    <origin rpy="-1.570796327 0 -1.570796327" xyz="0 0 0"/>
    <parent link="r_hip_roll_link"/>
    <child link="r_hip_pitch_link"/>
    <axis xyz="0 0 1"/>
    <limit effort="1000" lower="-1.2217" upper="1.2217" velocity="3"/>
    <!--<dynamics damping="0.5" friction="5"/>-->
  </joint>
  <transmission name="r_hip_pitch_joint_tran">
    <type>transmission_interface/SimpleTransmission</type>
    <joint name="r_hip_pitch_joint">
    </joint>
    <actuator name="r_hip_pitch_joint_motor">
    </actuator>
  </transmission>
  <!-- right hip pitch link -->
  <link name="r_hip_pitch_link">
    <visual>
      <origin rpy="0 0 0" xyz="0 0 0"/>
      <geometry>
        <mesh filename="meshes/r_hip_pitch_link.STL"/>
      </geometry>
    </visual>
    <inertial>
      <origin rpy="0 0 0" xyz="0.26753 4.9957E-05 -0.053132"/>
      <mass value="4.2544"/>
      <inertia ixx="0.0034501" ixy="-2.7593E-09" ixz="-0.0019797" iyy="0.010035" iyz="2.5351E-10" izz="0.01009"/>
    </inertial>
  </link>
  <!-- right knee pitch joint -->
  <joint name="r_knee_pitch_joint" type="revolute">
    <origin rpy="0 0 0" xyz="0.512778478308813 4.99999999867273E-05 -1.66647320091612E-05"/>
    <parent link="r_hip_pitch_link"/>
    <child link="r_knee_pitch_link"/>
    <axis xyz="0 0 1"/>
    <limit effort="1000" lower="-1.570796327" upper="1.570796327" velocity="3"/>
    <!--<dynamics damping="0.5" friction="5"/>-->
  </joint>
  <transmission name="r_knee_pitch_joint_tran">
    <type>transmission_interface/SimpleTransmission</type>
    <joint name="r_knee_pitch_joint">
    </joint>
    <actuator name="r_knee_pitch_joint_motor">
    </actuator>
  </transmission>
  <!-- right knee pitch link -->
  <link name="r_knee_pitch_link">
    <visual>
      <origin rpy="0 0 0" xyz="0 0 0"/>
      <geometry>
        <mesh filename="meshes/r_knee_pitch_link.STL"/>
      </geometry>
    </visual>
    <inertial>
      <origin rpy="0 0 0" xyz="0.13396 0.00063335 -0.00486"/>
      <mass value="3.4875"/>
      <inertia ixx="0.0064812" ixy="1.2949E-05" ixz="2.8064E-05" iyy="0.019762" iyz="-1.0389E-05" izz="0.017354"/>
    </inertial>
  </link>
  <!-- right ankle pitch joint -->
  <joint name="r_ankle_pitch_joint" type="revolute">
    <origin rpy="0 0 0.0" xyz="0.370000000000006 -3.16358749707368E-05 -0.00249999999999943"/>
    <parent link="r_knee_pitch_link"/>
    <child link="r_ankle_pitch_link"/>
    <axis xyz="0 0 1"/>
    <limit effort="1000" lower="-0.5236" upper="0.1745" velocity="3"/>
    <!--<dynamics damping="0.5" friction="2.0"/>-->
  </joint>
  <transmission name="r_ankle_pitch_joint_tran">
    <type>transmission_interface/SimpleTransmission</type>
    <joint name="r_ankle_pitch_joint">
    </joint>
    <actuator name="r_ankle_pitch_joint_motor">
    </actuator>
  </transmission>
  <!-- right ankle pitch link -->
  <link name="r_ankle_pitch_link">
    <visual>
      <origin rpy="0 0 0" xyz="0 0 0"/>
      <geometry>
        <mesh filename="meshes/r_ankle_pitch_link.STL"/>
      </geometry>
    </visual>
    <inertial>
      <origin rpy="0 0 0" xyz="-0.029867 0.001045 0.000556"/>
      <mass value="2.4242"/>
      <inertia ixx="0.0025143" ixy="-0.00025651" ixz="1.5321E-12" iyy="0.0045125" iyz="9.9589E-10" izz="0.0049235"/>
    </inertial>
  </link>
  <!-- right ankle roll joint -->
  <joint name="r_ankle_roll_joint" type="revolute">
    <origin rpy="1.570796327 0 0" xyz="0 0 0"/>
    <parent link="r_ankle_pitch_link"/>
    <child link="r_ankle_roll_link"/>
    <axis xyz="0 0 1"/>
    <limit effort="1000" lower="-0.3491" upper="0.3491" velocity="3"/>
    <!-- <dynamics damping="0.5" friction="2.0"/> -->
  </joint>
  <transmission name="r_ankle_roll_joint_tran">
    <type>transmission_interface/SimpleTransmission</type>
    <joint name="r_ankle_roll_joint">
    </joint>
    <actuator name="r_ankle_roll_joint_motor">
    </actuator>
  </transmission>
  <!-- right ankle roll link -->
  <link name="r_ankle_roll_link">
    <visual>
      <origin rpy="0 0 0" xyz="0 0 0"/>
      <geometry>
        <mesh filename="meshes/r_ankle_roll_link.STL"/>
      </geometry>
    </visual>
    <inertial>
      <origin rpy="0 0 0" xyz="0.073422 7.2094E-05 0.063933"/>
      <mass value="1.8533"/>
      <inertia ixx="0.0086813" ixy="1.0356E-05" ixz="0.00024346" iyy="0.0084051" iyz="-0.00012301" izz="0.0013018"/>
    </inertial>
  </link>
  <!-- left hip yaw joint -->
  <joint name="l_hip_yaw_joint" type="revolute">
    <origin rpy="0 0 -0.0" xyz="-0.0775 0 -0.14512"/>
    <parent link="base_footprint"/>
    <child link="l_hip_yaw_link"/>
    <axis xyz="0 0 1"/>
    <limit effort="1000" lower="-3.1416" upper="3.1416" velocity="3"/>
    <!-- <dynamics damping="0.5" friction="5"/> -->
  </joint>
  <transmission name="l_hip_yaw_joint_tran">
    <type>transmission_interface/SimpleTransmission</type>
    <joint name="l_hip_yaw_joint">
    </joint>
    <actuator name="l_hip_yaw_joint_motor">
    </actuator>
  </transmission>
  <!-- left hip yaw link -->
  <link name="l_hip_yaw_link">
    <visual>
      <origin rpy="0 0 0" xyz="0 0 0"/>
      <geometry>
        <mesh filename="meshes/l_hip_yaw_link.STL"/>
      </geometry>
    </visual>
    <inertial>
      <origin rpy="0 0 0" xyz="0.00063365 -0.00053469 0.063496"/>
      <mass value="1.6968"/>
      <inertia ixx="0.0022702" ixy="-2.5061E-10" ixz="6.6464E-06" iyy="0.0026746" iyz="-5.1468E-09" izz="0.001238"/>
    </inertial>
  </link>
  <!-- left hip roll joint-->
  <joint name="l_hip_roll_joint" type="revolute">
    <origin rpy="1.570796327 0 3.141592654" xyz="0 0 0"/>
    <parent link="l_hip_yaw_link"/>
    <child link="l_hip_roll_link"/>
    <axis xyz="0 0 1"/>
    <limit effort="1000" lower="-0.01" upper="0.5236" velocity="3"/>
    <!-- <dynamics damping="0.5" friction="5"/> -->
  </joint>
  <transmission name="l_hip_roll_joint_tran">
    <type>transmission_interface/SimpleTransmission</type>
    <joint name="l_hip_roll_joint">
    </joint>
    <actuator name="l_hip_roll_joint_motor">
    </actuator>
  </transmission>
  <!-- left hip roll link -->
  <link name="l_hip_roll_link">
    <visual>
      <origin rpy="0 0 0" xyz="0 0 0"/>
      <geometry>
        <mesh filename="meshes/l_hip_roll_link.STL"/>
      </geometry>
    </visual>
    <inertial>
      <origin rpy="0 0 0" xyz="0.07196 0.0061153 -0.0005211"/>
      <mass value="1.1884"/>
      <inertia ixx="0.00098222" ixy="-9.9265E-08" ixz="4.9766E-09" iyy="0.00097045" iyz="-9.7282E-08" izz="0.00092365"/>
    </inertial>
  </link>
  <!-- left hip pitch joint -->
  <joint name="l_hip_pitch_joint" type="revolute">
    <origin rpy="-1.570796327 0 -1.570796327" xyz="0 0 0"/>
    <parent link="l_hip_roll_link"/>
    <child link="l_hip_pitch_link"/>
    <axis xyz="0 0 1"/>
    <limit effort="1000" lower="-1.2217" upper="1.2217" velocity="3"/>
    <!-- <dynamics damping="0.5" friction="5"/> -->
  </joint>
  <transmission name="l_hip_pitch_joint_tran">
    <type>transmission_interface/SimpleTransmission</type>
    <joint name="l_hip_pitch_joint">
    </joint>
    <actuator name="l_hip_pitch_joint_motor">
    </actuator>
  </transmission>
  <!-- left hip pitch link -->
  <link name="l_hip_pitch_link">
    <visual>
      <origin rpy="0 0 0" xyz="0 0 0"/>
      <geometry>
        <mesh filename="meshes/l_hip_pitch_link.STL"/>
      </geometry>
    </visual>
    <inertial>
      <origin rpy="0 0 0" xyz="0.26752 4.6211E-05 0.053152"/>
      <mass value="4.2544"/>
      <inertia ixx="0.0034527" ixy="-3.1056E-08" ixz="0.0019797" iyy="0.010032" iyz="-1.4618E-10" izz="0.01009"/>
    </inertial>
  </link>
  <!-- left knee pitch joint -->
  <joint name="l_knee_pitch_joint" type="revolute">
    <origin rpy="0 0 0" xyz="0.512778478308813 5.00027201116859E-05 1.66647320003488E-05"/>
    <parent link="l_hip_pitch_link"/>
    <child link="l_knee_pitch_link"/>
    <axis xyz="0 0 1"/>
    <limit effort="1000" lower="-1.570796327" upper="1.570796327" velocity="3"/>
    <!-- <dynamics damping="0.5" friction="5"/> -->
  </joint>
  <transmission name="l_knee_pitch_joint_tran">
    <type>transmission_interface/SimpleTransmission</type>
    <joint name="l_knee_pitch_joint">
    </joint>
    <actuator name="l_knee_pitch_joint_motor">
    </actuator>
  </transmission>
  <!-- left knee pitch link -->
  <link name="l_knee_pitch_link">
    <visual>
      <origin rpy="0 0 0" xyz="0 0 0"/>
      <geometry>
        <mesh filename="meshes/l_knee_pitch_link.STL"/>
      </geometry>
    </visual>
    <inertial>
      <origin rpy="0 0 0" xyz="0.13547 0.00068516 0.00486"/>
      <mass value="3.4875"/>
      <inertia ixx="0.0064814" ixy="1.2524E-05" ixz="-2.7966E-05" iyy="0.019762" iyz="1.0417E-05" izz="0.017354"/>
    </inertial>
  </link>
  <!-- left ankle pitch joint -->
  <joint name="l_ankle_pitch_joint" type="revolute">
    <origin rpy="0 0 0.0" xyz="0.3715 3.1633E-05 0.0025"/>
    <parent link="l_knee_pitch_link"/>
    <child link="l_ankle_pitch_link"/>
    <axis xyz="0 0 1"/>
    <limit effort="1000" lower="-0.5236" upper="0.1745" velocity="3"/>
    <!-- <dynamics damping="0.5" friction="2.0"/> -->
  </joint>
  <transmission name="l_ankle_pitch_joint_tran">
    <type>transmission_interface/SimpleTransmission</type>
    <joint name="l_ankle_pitch_joint">
    </joint>
    <actuator name="l_ankle_pitch_joint_motor">
    </actuator>
  </transmission>
  <!-- left ankle pitch link -->
  <link name="l_ankle_pitch_link">
    <visual>
      <origin rpy="0 0 0" xyz="0 0 0"/>
      <geometry>
        <mesh filename="meshes/l_ankle_pitch_link.STL"/>
      </geometry>
    </visual>
    <inertial>
      <origin rpy="0 0 0" xyz="-0.029808 0.001045 3.1135E-08"/>
      <mass value="2.4242"/>
      <inertia ixx="0.0025143" ixy="-0.00025651" ixz="1.1633E-12" iyy="0.0045125" iyz="6.7196E-10" izz="0.0049235"/>
    </inertial>
  </link>
  <!-- left ankle roll pitch -->
  <joint name="l_ankle_roll_joint" type="revolute">
    <origin rpy="1.570796327 0 0" xyz="0 0 0"/>
    <parent link="l_ankle_pitch_link"/>
    <child link="l_ankle_roll_link"/>
    <axis xyz="0 0 1"/>
    <limit effort="1000" lower="-0.3491" upper="0.3491" velocity="3"/>
    <!-- <dynamics damping="0.5" friction="2.0"/> -->
  </joint>
  <transmission name="l_ankle_roll_joint_tran">
    <type>transmission_interface/SimpleTransmission</type>
    <joint name="l_ankle_roll_joint">
    </joint>
    <actuator name="l_ankle_roll_joint_motor">
    </actuator>
  </transmission>
  <!-- left ankle roll link -->
  <link name="l_ankle_roll_link">
    <visual>
      <origin rpy="0 0 0" xyz="0 0 0"/>
      <geometry>
        <mesh filename="meshes/l_ankle_roll_link.STL"/>
      </geometry>
    </visual>
    <inertial>
      <origin rpy="0 0 0" xyz="0.073422 -5.3261E-05 0.063946"/>
      <mass value="1.8533"/>
      <inertia ixx="0.008682" ixy="-1.0255E-05" ixz="0.00024351" iyy="0.0084057" iyz="0.00012332" izz="0.0013019"/>
    </inertial>
  </link>
</robot>

